Workbook
Name Fixed_hosting_cost_growth: 'BP input data'!$B$32
Name Basic_monthly_subscription: 'Business model'!$B$2
Name Dev_team_start_month: 'BP input data'!$C$38:$C$47
Name Team_months: 'BP input data'!$D$36:$D$58
Name Basic_yearly_subscription: 'Business model'!$B$3
Name Dev_team_months: 'BP input data'!$D$38:$D$47
Name CAC_cap: 'BP input data'!$B$25
Name Module_min_price: 'Business model'!$B$8
Name Variable_hosting_cost: 'BP input data'!$B$33
Name Fixed_hosting_cost: 'BP input data'!$B$31
Name Team_start_month: 'BP input data'!$C$36:$C$58
Name Enterprise_monthly_subscription: 'Business model'!$B$6
Name SM_team_value: 'BP input data'!$B$51:$B$55
Name Dev_team_value: 'BP input data'!$B$38:$B$47
Name Team_value: 'BP input data'!$B$36:$B$58
Name Pre_launch_months: 'BP input data'!$B$4
Name SM_team_months: 'BP input data'!$D$51:$D$55
Name SM_team_start_month: 'BP input data'!$C$51:$C$55
Name Pro_monthly_subscription: 'Business model'!$B$4
Name Online_marketing_start_month: 'BP input data'!$B$14
Name CAC_growth: 'BP input data'!$B$24
Name Enterprise_yearly_subscription: 'Business model'!$B$7
Name Pro_yearly_subscription: 'Business model'!$B$5
Name Module_max_price: 'Business model'!$B$9

Sheet Summary
A1: Inputs
A2: Month CEO stops with founder-led sales | B2: 10
A3: BD people starting year 1 | B3: 2
A4: BD people starting year 2 | B4: 8
A5: BD people starting year 3 | B5: 12
A6: BD sales per month (Basic) | B6: 5
A7: BD sales per month (Pro) | B7: 3
A8: BD sales per month (Enterprise) | B8: 1
A9: Monthly/yearly subscription split | B9: 0.1
A10: Basic tier marketing % split | B10: 0.1
A11: Pro tier marketing % split | B11: 0.1
A12: Online marketing start month | B12: 1
A13: Initial monthly marketing spend | B13: 5000
... A23: Churn (Enterprise) | B23: 0.0025
A25: Outputs
B26: Pre-launch | C26: Year 1 | D26: Year 2 | E26: Year 3 | F26: Year 4 | G26: Year 5 | H26: TOTAL
A27: Revenue | B27: ='Business plan'!B29 -> 0 | C27: ='Business plan'!C29 -> 7924992.1 | D27: ='Business plan'!O29 -> 84628803 | E27: ='Business plan'!AA29 -> 4.4144914e+08 | F27: ='Business plan'!AM29 -> 8.7304622e+08 | G27: ='Business plan'!AY29 -> 1249684607 | H27: =sum(B27:G27) -> 2656733762
A28: Costs | B28: ='Business plan'!B42 -> 383000 | C28: ='Business plan'!C42 -> 1766386.3 | D28: ='Business plan'!O42 -> 10774813 | E28: ='Business plan'!AA42 -> 37850812 | F28: ='Business plan'!AM42 -> 59901830 | G28: ='Business plan'!AY42 -> 78981646 | H28: =sum(B28:G28) -> 1.8965849e+08
A29: Profit | B29: =B27-B28 -> -383000 | C29: =C27-C28 -> 6158605.8 | D29: =D27-D28 -> 73853990 | E29: =E27-E28 -> 4.0359833e+08 | F29: =F27-F28 -> 8.1314439e+08 | G29: =G27-G28 -> 1170702961 | H29: =sum(B29:G29) -> 2467075275
A30: Gross profit margin | C30: =C29/C27 -> 0.77711192 | D30: =D29/D27 -> 0.87268149 | E30: =E29/E27 -> 0.91425782 | F30: =F29/F27 -> 0.93138756 | G30: =G29/G27 -> 0.93679874 | H30: =H29/H27 -> 0.92861216
B32: Basic | C32: Pro | D32: Enterprise
A33: Customer lifetime value (CLTV) | B33: =(('Business model'!$B$2*'BP input data'!$B$5)+('Business model'!$B$3*(1-'BP input data'!$B$5)/12))/'BP input data'!$B$26 -> 85000 | C33: =(('Business model'!$B$4*'BP input data'!$B$5)+('Business model'!$B$5*(1-'BP input data'!$B$5)/12))/'BP input data'!$B$27 -> 850000 | D33: =(('Business model'!$B$6*'BP input data'!$B$5)+('Business model'!$B$7*(1-'BP input data'!$B$5)/12))/'BP input data'!$B$28 -> 2720000
A34: LTV:CAC | B34: =B33/'BP input data'!$B$21 -> 106.25 | C34: =C33/'BP input data'!$B$22 -> 708.33333 | D34: =D33/'BP input data'!$B$23 -> 1813.3333
A36: Investment needed | B36: ='Investment need'!B23 -> 482415.42
A37: MoM profitability month | B37: {=INDEX('Business plan'!C2:BJ2, MATCH(TRUE, INDEX('Business plan'!C45:BJ45 > 0, 0), 0))} -> 2
A38: Cumulative profitability month | B38: {=INDEX('Investment need'!C2:BJ2, MATCH(TRUE, INDEX('Investment need'!C19:BJ19 > 0, 0), 0))} -> 5
A39: Monthly burn rate (pre-revenue) | B39: ='Business plan'!C40 -> 56927.083
A40: Runway (pre-revenue) | B40: =(B36-'Business plan'!B40)/B39 -> 1.7463641

Sheet Investment need
A1: Year | B1: Pre-launch | C1: 1 | O1: =C1+1 -> 2 | AA1: =O1+1 -> 3 | AM1: =AA1+1 -> 4 | AY1: =AM1+1 -> 5
A2: Month | C2: 1 | D2: =C2+1 -> 2 | E2: =D2+1 -> 3 | F2: =E2+1 -> 4 | G2: =F2+1 -> 5 | H2: =G2+1 -> 6 | I2: =H2+1 -> 7 | J2: =I2+1 -> 8 | K2: =J2+1 -> 9 | ... BJ2: =BI2+1 -> 60
A4: Costs
A5: Dev team | B5: =Pre_launch_months*SUMPRODUCT( (Dev_team_start_month <= COLUMN()-2) * (ISBLANK(Dev_team_months) + (COLUMN()-2 <= (Dev_team_start_month + Dev_team_months -1))) * Dev_team_value ) -> 42000 | C5: =SUMPRODUCT( (Dev_team_start_month <= COLUMN()-2) * (ISBLANK(Dev_team_months) + (COLUMN()-2 <= (Dev_team_start_month + Dev_team_months -1))) * Dev_team_value ) -> 19000 | D5: =SUMPRODUCT( (Dev_team_start_month <= COLUMN()-2) * (ISBLANK(Dev_team_months) + (COLUMN()-2 <= (Dev_team_start_month + Dev_team_months -1))) * Dev_team_value ) -> 19000 | E5: =SUMPRODUCT( (Dev_team_start_month <= COLUMN()-2) * (ISBLANK(Dev_team_months) + (COLUMN()-2 <= (Dev_team_start_month + Dev_team_months -1))) * Dev_team_value ) -> 25000 | F5: =SUMPRODUCT( (Dev_team_start_month <= COLUMN()-2) * (ISBLANK(Dev_team_months) + (COLUMN()-2 <= (Dev_team_start_month + Dev_team_months -1))) * Dev_team_value ) -> 37000 | G5: =SUMPRODUCT( (Dev_team_start_month <= COLUMN()-2) * (ISBLANK(Dev_team_months) + (COLUMN()-2 <= (Dev_team_start_month + Dev_team_months -1))) * Dev_team_value ) -> 37000 | H5: =SUMPRODUCT( (Dev_team_start_month <= COLUMN()-2) * (ISBLANK(Dev_team_months) + (COLUMN()-2 <= (Dev_team_start_month + Dev_team_months -1))) * Dev_team_value ) -> 37000 | I5: =SUMPRODUCT( (Dev_team_start_month <= COLUMN()-2) * (ISBLANK(Dev_team_months) + (COLUMN()-2 <= (Dev_team_start_month + Dev_team_months -1))) * Dev_team_value ) -> 47000 | J5: =SUMPRODUCT( (Dev_team_start_month <= COLUMN()-2) * (ISBLANK(Dev_team_months) + (COLUMN()-2 <= (Dev_team_start_month + Dev_team_months -1))) * Dev_team_value ) -> 47000 | ... BJ5: =SUMPRODUCT( (Dev_team_start_month <= COLUMN()-2) * (ISBLANK(Dev_team_months) + (COLUMN()-2 <= (Dev_team_start_month + Dev_team_months -1))) * Dev_team_value ) -> 51000
A6: S&M team | B6: =Pre_launch_months*SUMPRODUCT( (SM_team_start_month <= COLUMN()-2) * (ISBLANK(SM_team_months) + (COLUMN()-2 <= (SM_team_start_month + SM_team_months -1))) * SM_team_value ) -> 0 | C6: =SUMPRODUCT( (SM_team_start_month <= COLUMN()-2) * (ISBLANK(SM_team_months) + (COLUMN()-2 <= (SM_team_start_month + SM_team_months -1))) * SM_team_value ) -> 14500 | D6: =SUMPRODUCT( (SM_team_start_month <= COLUMN()-2) * (ISBLANK(SM_team_months) + (COLUMN()-2 <= (SM_team_start_month + SM_team_months -1))) * SM_team_value ) -> 14500 | E6: =SUMPRODUCT( (SM_team_start_month <= COLUMN()-2) * (ISBLANK(SM_team_months) + (COLUMN()-2 <= (SM_team_start_month + SM_team_months -1))) * SM_team_value ) -> 14500 | F6: =SUMPRODUCT( (SM_team_start_month <= COLUMN()-2) * (ISBLANK(SM_team_months) + (COLUMN()-2 <= (SM_team_start_month + SM_team_months -1))) * SM_team_value ) -> 14500 | G6: =SUMPRODUCT( (SM_team_start_month <= COLUMN()-2) * (ISBLANK(SM_team_months) + (COLUMN()-2 <= (SM_team_start_month + SM_team_months -1))) * SM_team_value ) -> 14500 | H6: =SUMPRODUCT( (SM_team_start_month <= COLUMN()-2) * (ISBLANK(SM_team_months) + (COLUMN()-2 <= (SM_team_start_month + SM_team_months -1))) * SM_team_value ) -> 14500 | I6: =SUMPRODUCT( (SM_team_start_month <= COLUMN()-2) * (ISBLANK(SM_team_months) + (COLUMN()-2 <= (SM_team_start_month + SM_team_months -1))) * SM_team_value ) -> 17000 | J6: =SUMPRODUCT( (SM_team_start_month <= COLUMN()-2) * (ISBLANK(SM_team_months) + (COLUMN()-2 <= (SM_team_start_month + SM_team_months -1))) * SM_team_value ) -> 17000 | ... BJ6: =SUMPRODUCT( (SM_team_start_month <= COLUMN()-2) * (ISBLANK(SM_team_months) + (COLUMN()-2 <= (SM_team_start_month + SM_team_months -1))) * SM_team_value ) -> 137000
A7: Product development | B7: ='Business plan'!B34+B5 -> 302000 | C7: ='Business plan'!C34+C5 -> 19000 | D7: ='Business plan'!D34+D5 -> 19000 | E7: ='Business plan'!E34+E5 -> 25000 | F7: ='Business plan'!F34+F5 -> 37000 | G7: ='Business plan'!G34+G5 -> 37000 | H7: ='Business plan'!H34+H5 -> 37000 | I7: ='Business plan'!I34+I5 -> 47000 | ... BJ7: ='Business plan'!BJ34+BJ5 -> 51000
A8: Marketing | B8: ='Business plan'!B35 | C8: ='Business plan'!C35 -> 5000 | D8: ='Business plan'!D35 -> 6250 | E8: ='Business plan'!E35 -> 7812.5 | F8: ='Business plan'!F35 -> 9765.625 | G8: ='Business plan'!G35 -> 12207.031 | H8: ='Business plan'!H35 -> 15258.789 | I8: ='Business plan'!I35 -> 19073.486 | ... BJ8: ='Business plan'!BJ35 -> 1000000
A9: Hosting | B9: ='Business plan'!B36 | C9: ='Business plan'!C36 -> 2927.0833 | D9: ='Business plan'!D36 -> 8629.6988 | E9: ='Business plan'!E36 -> 14641.91 | F9: ='Business plan'!F36 -> 23389.119 | G9: ='Business plan'!G36 -> 32434.392 | H9: ='Business plan'!H36 -> 41865.038 | I9: ='Business plan'!I36 -> 52112.784 | ... BJ9: ='Business plan'!BJ36 -> 6019679.8
A10: Team | B10: ='Business plan'!B37-B5 -> 36000 | C10: ='Business plan'!C37-C5 -> 25500 | D10: ='Business plan'!D37-D5 -> 25500 | E10: ='Business plan'!E37-E5 -> 25500 | F10: ='Business plan'!F37-F5 -> 25500 | G10: ='Business plan'!G37-G5 -> 25500 | H10: ='Business plan'!H37-H5 -> 25500 | I10: ='Business plan'!I37-I5 -> 32000 | ... BJ10: ='Business plan'!BJ37-BJ5 -> 164500
A11: Services | B11: ='Business plan'!B38 -> 12000 | C11: ='Business plan'!C38 -> 3500 | D11: ='Business plan'!D38 -> 3500 | E11: ='Business plan'!E38 -> 3500 | F11: ='Business plan'!F38 -> 3500 | G11: ='Business plan'!G38 -> 3500 | H11: ='Business plan'!H38 -> 3500 | I11: ='Business plan'!I38 -> 3500 | ... BJ11: ='Business plan'!BJ38 -> 3500
A12: Misc | B12: ='Business plan'!B39 -> 33000 | C12: ='Business plan'!C39 -> 1000 | D12: ='Business plan'!D39 -> 1000 | E12: ='Business plan'!E39 -> 1000 | F12: ='Business plan'!F39 -> 1000 | G12: ='Business plan'!G39 -> 1000 | H12: ='Business plan'!H39 -> 1000 | I12: ='Business plan'!I39 -> 28000 | ... BJ12: ='Business plan'!BJ39 -> 1000
A14: Grouped while at a loss
A15: Development | B15: =B7 -> 302000 | C15: =if(C$2<=$B$25,C7,0) -> 19000 | D15: =if(D$2<=$B$25,D7,0) -> 19000 | E15: =if(E$2<=$B$25,E7,0) -> 25000 | F15: =if(F$2<=$B$25,F7,0) -> 37000 | G15: =if(G$2<=$B$25,G7,0) -> 37000 | H15: =if(H$2<=$B$25,H7,0) -> 0 | I15: =if(I$2<=$B$25,I7,0) -> 0 | J15: =if(J$2<=$B$25,J7,0) -> 0 | ... BJ15: =if(BJ$2<=$B$25,BJ7,0) -> 0
A16: Sales & Marketing | B16: =B8+B6 -> 0 | C16: =if(C$2<=$B$25,C8+C6,0) -> 19500 | D16: =if(D$2<=$B$25,D8+D6,0) -> 20750 | E16: =if(E$2<=$B$25,E8+E6,0) -> 22312.5 | F16: =if(F$2<=$B$25,F8+F6,0) -> 24265.625 | G16: =if(G$2<=$B$25,G8+G6,0) -> 26707.031 | H16: =if(H$2<=$B$25,H8+H6,0) -> 0 | I16: =if(I$2<=$B$25,I8+I6,0) -> 0 | J16: =if(J$2<=$B$25,J8+J6,0) -> 0 | ... BJ16: =if(BJ$2<=$B$25,BJ8+BJ6,0) -> 0
A17: Operations | B17: =sum(B9:B12)-B6 -> 81000 | C17: =if(C$2<=$B$25,sum(C9:C12)-C6,0) -> 18427.083 | D17: =if(D$2<=$B$25,sum(D9:D12)-D6,0) -> 24129.699 | E17: =if(E$2<=$B$25,sum(E9:E12)-E6,0) -> 30141.91 | F17: =if(F$2<=$B$25,sum(F9:F12)-F6,0) -> 38889.119 | G17: =if(G$2<=$B$25,sum(G9:G12)-G6,0) -> 47934.392 | H17: =if(H$2<=$B$25,sum(H9:H12)-H6,0) -> 0 | I17: =if(I$2<=$B$25,sum(I9:I12)-I6,0) -> 0 | J17: =if(J$2<=$B$25,sum(J9:J12)-J6,0) -> 0 | ... BJ17: =if(BJ$2<=$B$25,sum(BJ9:BJ12)-BJ6,0) -> 0
A19: Cumulative profit | B19: ='Business plan'!B46 -> -383000 | C19: ='Business plan'!C46 -> -419491.67 | D19: ='Business plan'!D46 -> -411541.34 | E19: ='Business plan'!E46 -> -358621.44 | F19: ='Business plan'!F46 -> -221153.46 | G19: ='Business plan'!G46 -> 19753.033 | H19: ='Business plan'!H46 -> 372760.35 | I19: ='Business plan'!I46 -> 810402.16 | ... BJ19: ='Business plan'!BJ46 -> 2467075275
A21: Investment needed | B21: =-min(B19:BJ19) -> 419491.67
A22: Contingency | B22: 0.15
A23: Investment ask | B23: =B21*(1+B22) -> 482415.42
A25: Breakeven month | B25: {=INDEX('Business plan'!C2:BJ2, MATCH(TRUE, INDEX('Business plan'!C46:BJ46 > 0, 0), 0))} -> 5
B27: Total | C27: % | D27: Investment
A28: Development | B28: =sum(B15:BJ15) -> 439000 | C28: =B28/$B$31 -> 0.55355391 | D28: =$B$23*C28 -> 267042.94
A29: Sales & Marketing | B29: =sum(B16:BJ16) -> 113535.16 | C29: =B29/$B$31 -> 0.14316134 | D29: =$B$23*C29 -> 69063.239
A30: Operations | B30: =sum(B17:BJ17) -> 240522.2 | C30: =B30/$B$31 -> 0.30328475 | D30: =$B$23*C30 -> 146309.24
A31: Total | B31: =sum(B28:B30) -> 793057.36

Sheet Business plan
A1: Year | B1: Pre-launch | C1: 1 | O1: =C1+1 -> 2 | AA1: =O1+1 -> 3 | AM1: =AA1+1 -> 4 | AY1: =AM1+1 -> 5
A2: Month | C2: 1 | D2: =C2+1 -> 2 | E2: =D2+1 -> 3 | F2: =E2+1 -> 4 | G2: =F2+1 -> 5 | H2: =G2+1 -> 6 | I2: =H2+1 -> 7 | J2: =I2+1 -> 8 | K2: =J2+1 -> 9 | ... BJ2: =BI2+1 -> 60
A3: Revenue
A4: Direct sales
A5: BD reps | C5: =if('BP input data'!$B$8>C2,1,0)+Summary!$B$3 -> 3 | D5: =if('BP input data'!$B$8>D2,1,0)+Summary!$B$3 -> 3 | E5: =if('BP input data'!$B$8>E2,1,0)+Summary!$B$3 -> 3 | F5: =if('BP input data'!$B$8>F2,1,0)+Summary!$B$3 -> 3 | G5: =if('BP input data'!$B$8>G2,1,0)+Summary!$B$3 -> 3 | H5: =if('BP input data'!$B$8>H2,1,0)+Summary!$B$3 -> 3 | I5: =if('BP input data'!$B$8>I2,1,0)+Summary!$B$3 -> 3 | J5: =if('BP input data'!$B$8>J2,1,0)+Summary!$B$3 -> 3 | ... N5: =if('BP input data'!$B$8>N2,1,0)+Summary!$B$3 -> 2 | O5: =if('BP input data'!$B$8>O2,1,0)+Summary!$B$3+Summary!$B$4 -> 10 | P5: =if('BP input data'!$B$8>P2,1,0)+Summary!$B$3+Summary!$B$4 -> 10 | Q5: =if('BP input data'!$B$8>Q2,1,0)+Summary!$B$3+Summary!$B$4 -> 10 | R5: =if('BP input data'!$B$8>R2,1,0)+Summary!$B$3+Summary!$B$4 -> 10 | S5: =if('BP input data'!$B$8>S2,1,0)+Summary!$B$3+Summary!$B$4 -> 10 | T5: =if('BP input data'!$B$8>T2,1,0)+Summary!$B$3+Summary!$B$4 -> 10 | U5: =if('BP input data'!$B$8>U2,1,0)+Summary!$B$3+Summary!$B$4 -> 10 | V5: =if('BP input data'!$B$8>V2,1,0)+Summary!$B$3+Summary!$B$4 -> 10 | ... Z5: =if('BP input data'!$B$8>Z2,1,0)+Summary!$B$3+Summary!$B$4 -> 10 | AA5: =if('BP input data'!$B$8>AA2,1,0)+Summary!$B$3+Summary!$B$4+Summary!$B$5 -> 22 | AB5: =if('BP input data'!$B$8>AB2,1,0)+Summary!$B$3+Summary!$B$4+Summary!$B$5 -> 22 | AC5: =if('BP input data'!$B$8>AC2,1,0)+Summary!$B$3+Summary!$B$4+Summary!$B$5 -> 22 | AD5: =if('BP input data'!$B$8>AD2,1,0)+Summary!$B$3+Summary!$B$4+Summary!$B$5 -> 22 | AE5: =if('BP input data'!$B$8>AE2,1,0)+Summary!$B$3+Summary!$B$4+Summary!$B$5 -> 22 | AF5: =if('BP input data'!$B$8>AF2,1,0)+Summary!$B$3+Summary!$B$4+Summary!$B$5 -> 22 | AG5: =if('BP input data'!$B$8>AG2,1,0)+Summary!$B$3+Summary!$B$4+Summary!$B$5 -> 22 | AH5: =if('BP input data'!$B$8>AH2,1,0)+Summary!$B$3+Summary!$B$4+Summary!$B$5 -> 22 | ... BJ5: =if('BP input data'!$B$8>BJ2,1,0)+Summary!$B$3+Summary!$B$4+Summary!$B$5 -> 22
A6: New customers (Basic) | D6: =C$5*'BP input data'!$B9 -> 15 | E6: =D$5*'BP input data'!$B9 -> 15 | F6: =E$5*'BP input data'!$B9 -> 15 | G6: =F$5*'BP input data'!$B9 -> 15 | H6: =G$5*'BP input data'!$B9 -> 15 | I6: =H$5*'BP input data'!$B9 -> 15 | J6: =I$5*'BP input data'!$B9 -> 15 | K6: =J$5*'BP input data'!$B9 -> 15 | ... BJ6: =BI$5*'BP input data'!$B9 -> 110
A7: New customers (Pro) | F7: =C$5*'BP input data'!$B10 -> 9 | G7: =D$5*'BP input data'!$B10 -> 9 | H7: =E$5*'BP input data'!$B10 -> 9 | I7: =F$5*'BP input data'!$B10 -> 9 | J7: =G$5*'BP input data'!$B10 -> 9 | K7: =H$5*'BP input data'!$B10 -> 9 | L7: =I$5*'BP input data'!$B10 -> 9 | M7: =J$5*'BP input data'!$B10 -> 9 | ... BJ7: =BG$5*'BP input data'!$B10 -> 66
A8: New customers (Enterprise) | L8: =C$5*'BP input data'!$B11 -> 3 | M8: =D$5*'BP input data'!$B11 -> 3 | N8: =E$5*'BP input data'!$B11 -> 3 | O8: =F$5*'BP input data'!$B11 -> 3 | P8: =G$5*'BP input data'!$B11 -> 3 | Q8: =H$5*'BP input data'!$B11 -> 3 | R8: =I$5*'BP input data'!$B11 -> 3 | S8: =J$5*'BP input data'!$B11 -> 3 | ... BJ8: =BA$5*'BP input data'!$B11 -> 22
A9: Online marketing
A10: CAC (Basic) | C10: =if( C$2=Online_marketing_start_month,'BP input data'!$B$21,0) -> 800 | D10: =if(D$2=Online_marketing_start_month,'BP input data'!$B$21,if(D$2>Online_marketing_start_month,min('BP input data'!$B$21*CAC_cap,C10*(1+CAC_growth)),0)) -> 808 | E10: =if(E$2=Online_marketing_start_month,'BP input data'!$B$21,if(E$2>Online_marketing_start_month,min('BP input data'!$B$21*CAC_cap,D10*(1+CAC_growth)),0)) -> 816.08 | F10: =if(F$2=Online_marketing_start_month,'BP input data'!$B$21,if(F$2>Online_marketing_start_month,min('BP input data'!$B$21*CAC_cap,E10*(1+CAC_growth)),0)) -> 824.2408 | G10: =if(G$2=Online_marketing_start_month,'BP input data'!$B$21,if(G$2>Online_marketing_start_month,min('BP input data'!$B$21*CAC_cap,F10*(1+CAC_growth)),0)) -> 832.48321 | H10: =if(H$2=Online_marketing_start_month,'BP input data'!$B$21,if(H$2>Online_marketing_start_month,min('BP input data'!$B$21*CAC_cap,G10*(1+CAC_growth)),0)) -> 840.80804 | I10: =if(I$2=Online_marketing_start_month,'BP input data'!$B$21,if(I$2>Online_marketing_start_month,min('BP input data'!$B$21*CAC_cap,H10*(1+CAC_growth)),0)) -> 849.21612 | J10: =if(J$2=Online_marketing_start_month,'BP input data'!$B$21,if(J$2>Online_marketing_start_month,min('BP input data'!$B$21*CAC_cap,I10*(1+CAC_growth)),0)) -> 857.70828 | K10: =if(K$2=Online_marketing_start_month,'BP input data'!$B$21,if(K$2>Online_marketing_start_month,min('BP input data'!$B$21*CAC_cap,J10*(1+CAC_growth)),0)) -> 866.28536 | ... BJ10: =if(BJ$2=Online_marketing_start_month,'BP input data'!$B$21,if(BJ$2>Online_marketing_start_month,min('BP input data'!$B$21*CAC_cap,BI10*(1+CAC_growth)),0)) -> 1438.9677
A11: New customers (Basic) | C11: =if(C10>0,('BP input data'!$B$18*C$35)/C10,0) -> 0.625 | D11: =if(D10>0,('BP input data'!$B$18*D35)/D10,0) -> 0.77351485 | E11: =if(E10>0,('BP input data'!$B$18*E35)/E10,0) -> 0.95732036 | F11: =if(F10>0,('BP input data'!$B$18*F35)/F10,0) -> 1.1848024 | G11: =if(G10>0,('BP input data'!$B$18*G35)/G10,0) -> 1.4663396 | H11: =if(H10>0,('BP input data'!$B$18*H35)/H10,0) -> 1.8147768 | I11: =if(I10>0,('BP input data'!$B$18*I35)/I10,0) -> 2.2460109 | J11: =if(J10>0,('BP input data'!$B$18*J35)/J10,0) -> 2.7797164 | K11: =if(K10>0,('BP input data'!$B$18*K35)/K10,0) -> 3.4402431 | ... BJ11: =if(BJ10>0,('BP input data'!$B$18*BJ35)/BJ10,0) -> 69.494264
A12: CAC (Pro) | C12: =if( C$2=Online_marketing_start_month,'BP input data'!$B$22,0) -> 1200 | D12: =if(D$2=Online_marketing_start_month,'BP input data'!$B$22,if(D$2>Online_marketing_start_month,min('BP input data'!$B$22*CAC_cap,C12*(1+CAC_growth)),0)) -> 1212 | E12: =if(E$2=Online_marketing_start_month,'BP input data'!$B$22,if(E$2>Online_marketing_start_month,min('BP input data'!$B$22*CAC_cap,D12*(1+CAC_growth)),0)) -> 1224.12 | F12: =if(F$2=Online_marketing_start_month,'BP input data'!$B$22,if(F$2>Online_marketing_start_month,min('BP input data'!$B$22*CAC_cap,E12*(1+CAC_growth)),0)) -> 1236.3612 | G12: =if(G$2=Online_marketing_start_month,'BP input data'!$B$22,if(G$2>Online_marketing_start_month,min('BP input data'!$B$22*CAC_cap,F12*(1+CAC_growth)),0)) -> 1248.7248 | H12: =if(H$2=Online_marketing_start_month,'BP input data'!$B$22,if(H$2>Online_marketing_start_month,min('BP input data'!$B$22*CAC_cap,G12*(1+CAC_growth)),0)) -> 1261.2121 | I12: =if(I$2=Online_marketing_start_month,'BP input data'!$B$22,if(I$2>Online_marketing_start_month,min('BP input data'!$B$22*CAC_cap,H12*(1+CAC_growth)),0)) -> 1273.8242 | J12: =if(J$2=Online_marketing_start_month,'BP input data'!$B$22,if(J$2>Online_marketing_start_month,min('BP input data'!$B$22*CAC_cap,I12*(1+CAC_growth)),0)) -> 1286.5624 | K12: =if(K$2=Online_marketing_start_month,'BP input data'!$B$22,if(K$2>Online_marketing_start_month,min('BP input data'!$B$22*CAC_cap,J12*(1+CAC_growth)),0)) -> 1299.428 | ... BJ12: =if(BJ$2=Online_marketing_start_month,'BP input data'!$B$22,if(BJ$2>Online_marketing_start_month,min('BP input data'!$B$22*CAC_cap,BI12*(1+CAC_growth)),0)) -> 2158.4515
A13: New customers (Pro) | C13: =if(C12>0,('BP input data'!$B$19*C$35)/C12,0) -> 0.41666667 | D13: =if(D12>0,('BP input data'!$B$18*D37)/D12,0) -> 3.6716172 | E13: =if(E12>0,('BP input data'!$B$18*E37)/E12,0) -> 4.1254125 | F13: =if(F12>0,('BP input data'!$B$18*F37)/F12,0) -> 5.055157 | G13: =if(G12>0,('BP input data'!$B$18*G37)/G12,0) -> 5.005106 | H13: =if(H12>0,('BP input data'!$B$18*H37)/H12,0) -> 4.9555505 | I13: =if(I12>0,('BP input data'!$B$18*I37)/I12,0) -> 6.2017978 | J13: =if(J12>0,('BP input data'!$B$18*J37)/J12,0) -> 6.1403939 | K13: =if(K12>0,('BP input data'!$B$18*K37)/K12,0) -> 6.0795979 | ... BJ13: =if(BJ12>0,('BP input data'!$B$18*BJ37)/BJ12,0) -> 9.9840093
A14: CAC (Enterprise) | C14: =if( C$2=Online_marketing_start_month,'BP input data'!$B$23,0) -> 1500 | D14: =if(D$2=Online_marketing_start_month,'BP input data'!$B$23,if(D$2>Online_marketing_start_month,min('BP input data'!$B$23*CAC_cap,C14*(1+CAC_growth)),0)) -> 1515 | E14: =if(E$2=Online_marketing_start_month,'BP input data'!$B$23,if(E$2>Online_marketing_start_month,min('BP input data'!$B$23*CAC_cap,D14*(1+CAC_growth)),0)) -> 1530.15 | F14: =if(F$2=Online_marketing_start_month,'BP input data'!$B$23,if(F$2>Online_marketing_start_month,min('BP input data'!$B$23*CAC_cap,E14*(1+CAC_growth)),0)) -> 1545.4515 | G14: =if(G$2=Online_marketing_start_month,'BP input data'!$B$23,if(G$2>Online_marketing_start_month,min('BP input data'!$B$23*CAC_cap,F14*(1+CAC_growth)),0)) -> 1560.906 | H14: =if(H$2=Online_marketing_start_month,'BP input data'!$B$23,if(H$2>Online_marketing_start_month,min('BP input data'!$B$23*CAC_cap,G14*(1+CAC_growth)),0)) -> 1576.5151 | I14: =if(I$2=Online_marketing_start_month,'BP input data'!$B$23,if(I$2>Online_marketing_start_month,min('BP input data'!$B$23*CAC_cap,H14*(1+CAC_growth)),0)) -> 1592.2802 | J14: =if(J$2=Online_marketing_start_month,'BP input data'!$B$23,if(J$2>Online_marketing_start_month,min('BP input data'!$B$23*CAC_cap,I14*(1+CAC_growth)),0)) -> 1608.203 | K14: =if(K$2=Online_marketing_start_month,'BP input data'!$B$23,if(K$2>Online_marketing_start_month,min('BP input data'!$B$23*CAC_cap,J14*(1+CAC_growth)),0)) -> 1624.2851 | ... BJ14: =if(BJ$2=Online_marketing_start_month,'BP input data'!$B$23,if(BJ$2>Online_marketing_start_month,min('BP input data'!$B$23*CAC_cap,BI14*(1+CAC_growth)),0)) -> 2698.0644
A15: New customers (Enterprise) | C15: =if(C14>0,('BP input data'!$B$20*C$35)/C14,0) -> 2.6666667 | D15: =if(D14>0,('BP input data'!$B$20*D$35)/D14,0) -> 3.30033 | E15: =if(E14>0,('BP input data'!$B$20*E$35)/E14,0) -> 4.0845669 | F15: =if(F14>0,('BP input data'!$B$20*F$35)/F14,0) -> 5.055157 | G15: =if(G14>0,('BP input data'!$B$20*G$35)/G14,0) -> 6.2563825 | H15: =if(H14>0,('BP input data'!$B$20*H$35)/H14,0) -> 7.7430476 | I15: =if(I14>0,('BP input data'!$B$20*I$35)/I14,0) -> 9.5829797 | J15: =if(J14>0,('BP input data'!$B$20*J$35)/J14,0) -> 11.860123 | ... BJ15: =if(BJ14>0,('BP input data'!$B$20*BJ$35)/BJ14,0) -> 296.50886
A16: Summary
A17: Lost users (Basic) | D17: =C18*'BP input data'!$B$26 -> 0.00625 | E17: =D18*'BP input data'!$B$26 -> 0.16392265 | F17: =E18*'BP input data'!$B$26 -> 0.32185663 | G17: =F18*'BP input data'!$B$26 -> 0.48048608 | H17: =G18*'BP input data'!$B$26 -> 0.64034462 | I17: =H18*'BP input data'!$B$26 -> 0.80208894 | J17: =I18*'BP input data'!$B$26 -> 0.96652816 | K17: =J18*'BP input data'!$B$26 -> 1.13466 | ... BJ17: =BI18*'BP input data'!$B$26 -> 64.327069
A18: Total customers (Basic) | C18: =C6+C11 -> 0.625 | D18: =C18+D6+D11-D17 -> 16.392265 | E18: =D18+E6+E11-E17 -> 32.185663 | F18: =E18+F6+F11-F17 -> 48.048608 | G18: =F18+G6+G11-G17 -> 64.034462 | H18: =G18+H6+H11-H17 -> 80.208894 | I18: =H18+I6+I11-I17 -> 96.652816 | J18: =I18+J6+J11-J17 -> 113.466 | K18: =J18+K6+K11-K17 -> 130.77159 | ... BJ18: =BI18+BJ6+BJ11-BJ17 -> 6547.8741
A19: Lost users (Pro) | D19: =C20*'BP input data'!$B$27 -> 0.0020833333 | E19: =D20*'BP input data'!$B$27 -> 0.020431002 | F19: =E20*'BP input data'!$B$27 -> 0.04095591 | G19: =F20*'BP input data'!$B$27 -> 0.11102692 | H19: =G20*'BP input data'!$B$27 -> 0.18049731 | I19: =H20*'BP input data'!$B$27 -> 0.24937258 | J19: =I20*'BP input data'!$B$27 -> 0.3241347 | K19: =J20*'BP input data'!$B$27 -> 0.398216 | ... BJ19: =BI20*'BP input data'!$B$27 -> 14.300124
A20: Total customers (Pro) | C20: =C7+C13 -> 0.41666667 | D20: =C20+D7+D13-D19 -> 4.0862005 | E20: =D20+E7+E13-E19 -> 8.191182 | F20: =E20+F7+F13-F19 -> 22.205383 | G20: =F20+G7+G13-G19 -> 36.099462 | H20: =G20+H7+H13-H19 -> 49.874515 | I20: =H20+I7+I13-I19 -> 64.826941 | J20: =I20+J7+J13-J19 -> 79.6432 | K20: =J20+K7+K13-K19 -> 94.324582 | ... BJ20: =BI20+BJ7+BJ13-BJ19 -> 2921.7088
A21: Lost users (Enterprise) | D21: =C22*'BP input data'!$B$28 -> 0.0066666667 | E21: =D22*'BP input data'!$B$28 -> 0.014900825 | F21: =E22*'BP input data'!$B$28 -> 0.02507499 | G21: =F22*'BP input data'!$B$28 -> 0.037650195 | H21: =G22*'BP input data'!$B$28 -> 0.053197026 | I21: =H22*'BP input data'!$B$28 -> 0.072421652 | J21: =I22*'BP input data'!$B$28 -> 0.096198047 | K21: =J22*'BP input data'!$B$28 -> 0.12560786 | ... BJ21: =BI22*'BP input data'!$B$28 -> 35.780045
A22: Total customers (Enterprise) | C22: =C8+C15 -> 2.6666667 | D22: =C22+D8+D15-D21 -> 5.96033 | E22: =D22+E8+E15-E21 -> 10.029996 | F22: =E22+F8+F15-F21 -> 15.060078 | G22: =F22+G8+G15-G21 -> 21.27881 | H22: =G22+H8+H15-H21 -> 28.968661 | I22: =H22+I8+I15-I21 -> 38.479219 | J22: =I22+J8+J15-J21 -> 50.243144 | K22: =J22+K8+K15-K21 -> 64.795907 | ... BJ22: =BI22+BJ8+BJ15-BJ21 -> 14594.747
A23: Sales (Basic) | C23: =((C18*'Business model'!$B$2*'BP input data'!$B$5)+(C18*'Business model'!$B$3*(1-'BP input data'!$B$5)/12)) -> 531.25 | D23: =((D18*'Business model'!$B$2*'BP input data'!$B$5)+(D18*'Business model'!$B$3*(1-'BP input data'!$B$5)/12)) -> 13933.425 | E23: =((E18*'Business model'!$B$2*'BP input data'!$B$5)+(E18*'Business model'!$B$3*(1-'BP input data'!$B$5)/12)) -> 27357.813 | F23: =((F18*'Business model'!$B$2*'BP input data'!$B$5)+(F18*'Business model'!$B$3*(1-'BP input data'!$B$5)/12)) -> 40841.317 | G23: =((G18*'Business model'!$B$2*'BP input data'!$B$5)+(G18*'Business model'!$B$3*(1-'BP input data'!$B$5)/12)) -> 54429.293 | H23: =((H18*'Business model'!$B$2*'BP input data'!$B$5)+(H18*'Business model'!$B$3*(1-'BP input data'!$B$5)/12)) -> 68177.56 | I23: =((I18*'Business model'!$B$2*'BP input data'!$B$5)+(I18*'Business model'!$B$3*(1-'BP input data'!$B$5)/12)) -> 82154.894 | J23: =((J18*'Business model'!$B$2*'BP input data'!$B$5)+(J18*'Business model'!$B$3*(1-'BP input data'!$B$5)/12)) -> 96446.104 | ... BJ23: =((BJ18*'Business model'!$B$2*'BP input data'!$B$5)+(BJ18*'Business model'!$B$3*(1-'BP input data'!$B$5)/12)) -> 5565693
A24: Sales (Pro) | C24: =((C20*'Business model'!$B$4*'BP input data'!$B$5)+(C20*'Business model'!$B$5*(1-'BP input data'!$B$5)/12)) -> 1770.8333 | D24: =((D20*'Business model'!$B$4*'BP input data'!$B$5)+(D20*'Business model'!$B$5*(1-'BP input data'!$B$5)/12)) -> 17366.352 | E24: =((E20*'Business model'!$B$4*'BP input data'!$B$5)+(E20*'Business model'!$B$5*(1-'BP input data'!$B$5)/12)) -> 34812.524 | F24: =((F20*'Business model'!$B$4*'BP input data'!$B$5)+(F20*'Business model'!$B$5*(1-'BP input data'!$B$5)/12)) -> 94372.878 | G24: =((G20*'Business model'!$B$4*'BP input data'!$B$5)+(G20*'Business model'!$B$5*(1-'BP input data'!$B$5)/12)) -> 153422.71 | H24: =((H20*'Business model'!$B$4*'BP input data'!$B$5)+(H20*'Business model'!$B$5*(1-'BP input data'!$B$5)/12)) -> 211966.69 | I24: =((I20*'Business model'!$B$4*'BP input data'!$B$5)+(I20*'Business model'!$B$5*(1-'BP input data'!$B$5)/12)) -> 275514.5 | J24: =((J20*'Business model'!$B$4*'BP input data'!$B$5)+(J20*'Business model'!$B$5*(1-'BP input data'!$B$5)/12)) -> 338483.6 | ... BJ24: =((BJ20*'Business model'!$B$4*'BP input data'!$B$5)+(BJ20*'Business model'!$B$5*(1-'BP input data'!$B$5)/12)) -> 12417262
A25: Sales (Enterprise) | C25: =((C22*'Business model'!$B$6*'BP input data'!$B$5)+(C22*'Business model'!$B$7*(1-'BP input data'!$B$5)/12)) -> 18133.333 | D25: =((D22*'Business model'!$B$6*'BP input data'!$B$5)+(D22*'Business model'!$B$7*(1-'BP input data'!$B$5)/12)) -> 40530.244 | E25: =((E22*'Business model'!$B$6*'BP input data'!$B$5)+(E22*'Business model'!$B$7*(1-'BP input data'!$B$5)/12)) -> 68203.973 | F25: =((F22*'Business model'!$B$6*'BP input data'!$B$5)+(F22*'Business model'!$B$7*(1-'BP input data'!$B$5)/12)) -> 102408.53 | G25: =((G22*'Business model'!$B$6*'BP input data'!$B$5)+(G22*'Business model'!$B$7*(1-'BP input data'!$B$5)/12)) -> 144695.91 | H25: =((H22*'Business model'!$B$6*'BP input data'!$B$5)+(H22*'Business model'!$B$7*(1-'BP input data'!$B$5)/12)) -> 196986.89 | I25: =((I22*'Business model'!$B$6*'BP input data'!$B$5)+(I22*'Business model'!$B$7*(1-'BP input data'!$B$5)/12)) -> 261658.69 | J25: =((J22*'Business model'!$B$6*'BP input data'!$B$5)+(J22*'Business model'!$B$7*(1-'BP input data'!$B$5)/12)) -> 341653.38 | ... BJ25: =((BJ22*'Business model'!$B$6*'BP input data'!$B$5)+(BJ22*'Business model'!$B$7*(1-'BP input data'!$B$5)/12)) -> 99244278
A26: Sales | C26: =C23+C24+C25 -> 20435.417 | D26: =D23+D24+D25 -> 71830.021 | E26: =E23+E24+E25 -> 130374.31 | F26: =F23+F24+F25 -> 237622.73 | G26: =G23+G24+G25 -> 352547.92 | H26: =H23+H24+H25 -> 477131.14 | I26: =I23+I24+I25 -> 619328.08 | J26: =J23+J24+J25 -> 776583.08 | ... BJ26: =BJ23+BJ24+BJ25 -> 1.1722723e+08
A27: Revenue (MRR) | B27: 0 | C27: =C26 -> 20435.417 | D27: =D26 -> 71830.021 | E27: =E26 -> 130374.31 | F27: =F26 -> 237622.73 | G27: =G26 -> 352547.92 | H27: =H26 -> 477131.14 | I27: =I26 -> 619328.08 | J27: =J26 -> 776583.08 | ... BJ27: =BJ26 -> 1.1722723e+08
A28: Cumulative revenue | B28: =B27 -> 0 | C28: =B28+C27 -> 20435.417 | D28: =C28+D27 -> 92265.438 | E28: =D28+E27 -> 222639.75 | F28: =E28+F27 -> 460262.47 | G28: =F28+G27 -> 812810.39 | H28: =G28+H27 -> 1289941.5 | I28: =H28+I27 -> 1909269.6 | J28: =I28+J27 -> 2685852.7 | ... BJ28: =BI28+BJ27 -> 2656733762
A29: Annual revenue (ARR) | B29: =B28 -> 0 | C29: =N28-B28 -> 7924992.1 | O29: =Z28-N28 -> 84628803 | AA29: =AL28-Z28 -> 4.4144914e+08 | AM29: =AX28-AL28 -> 8.7304622e+08 | AY29: =BJ28-AX28 -> 1249684607
A31: Costs
A32: Hosting (fixed) | C32: =Fixed_hosting_cost -> 2000 | D32: =C32*(1+Fixed_hosting_cost_growth) -> 2020 | E32: =D32*(1+Fixed_hosting_cost_growth) -> 2040.2 | F32: =E32*(1+Fixed_hosting_cost_growth) -> 2060.602 | G32: =F32*(1+Fixed_hosting_cost_growth) -> 2081.208 | H32: =G32*(1+Fixed_hosting_cost_growth) -> 2102.0201 | I32: =H32*(1+Fixed_hosting_cost_growth) -> 2123.0403 | J32: =I32*(1+Fixed_hosting_cost_growth) -> 2144.2707 | K32: =J32*(1+Fixed_hosting_cost_growth) -> 2165.7134 | ... BJ32: =BI32*(1+Fixed_hosting_cost_growth) -> 3597.4192
A33: Hosting (variable) | C33: =(Variable_hosting_cost*(C18+C20+C22)) -> 927.08333 | D33: =(Variable_hosting_cost*(D18+D20+D22)) -> 6609.6988 | E33: =(Variable_hosting_cost*(E18+E20+E22)) -> 12601.71 | F33: =(Variable_hosting_cost*(F18+F20+F22)) -> 21328.517 | G33: =(Variable_hosting_cost*(G18+G20+G22)) -> 30353.184 | H33: =(Variable_hosting_cost*(H18+H20+H22)) -> 39763.018 | I33: =(Variable_hosting_cost*(I18+I20+I22)) -> 49989.744 | J33: =(Variable_hosting_cost*(J18+J20+J22)) -> 60838.087 | ... BJ33: =(Variable_hosting_cost*(BJ18+BJ20+BJ22)) -> 6016082.4
A34: Product development | B34: ='BP input data'!$B$60+'BP input data'!$B$62 -> 260000 | C34: ='BP input data'!$B$61 -> 0 | D34: ='BP input data'!$B$61 -> 0 | E34: ='BP input data'!$B$61 -> 0 | F34: ='BP input data'!$B$61 -> 0 | G34: ='BP input data'!$B$61 -> 0 | H34: ='BP input data'!$B$61 -> 0 | I34: ='BP input data'!$B$61 -> 0 | J34: ='BP input data'!$B$61 -> 0 | ... BJ34: ='BP input data'!$B$61 -> 0
A35: Marketing | C35: =if( C2='BP input data'!$B$14,'BP input data'!$B$15,0) -> 5000 | D35: =if( D2='BP input data'!$B$14,'BP input data'!$B$15,if( D2>'BP input data'!$B$14,min(C35*(1+'BP input data'!$B$16),'BP input data'!$B$17),0)) -> 6250 | E35: =if( E2='BP input data'!$B$14,'BP input data'!$B$15,if( E2>'BP input data'!$B$14,min(D35*(1+'BP input data'!$B$16),'BP input data'!$B$17),0)) -> 7812.5 | F35: =if( F2='BP input data'!$B$14,'BP input data'!$B$15,if( F2>'BP input data'!$B$14,min(E35*(1+'BP input data'!$B$16),'BP input data'!$B$17),0)) -> 9765.625 | G35: =if( G2='BP input data'!$B$14,'BP input data'!$B$15,if( G2>'BP input data'!$B$14,min(F35*(1+'BP input data'!$B$16),'BP input data'!$B$17),0)) -> 12207.031 | H35: =if( H2='BP input data'!$B$14,'BP input data'!$B$15,if( H2>'BP input data'!$B$14,min(G35*(1+'BP input data'!$B$16),'BP input data'!$B$17),0)) -> 15258.789 | I35: =if( I2='BP input data'!$B$14,'BP input data'!$B$15,if( I2>'BP input data'!$B$14,min(H35*(1+'BP input data'!$B$16),'BP input data'!$B$17),0)) -> 19073.486 | J35: =if( J2='BP input data'!$B$14,'BP input data'!$B$15,if( J2>'BP input data'!$B$14,min(I35*(1+'BP input data'!$B$16),'BP input data'!$B$17),0)) -> 23841.858 | K35: =if( K2='BP input data'!$B$14,'BP input data'!$B$15,if( K2>'BP input data'!$B$14,min(J35*(1+'BP input data'!$B$16),'BP input data'!$B$17),0)) -> 29802.322 | ... BJ35: =if( BJ2='BP input data'!$B$14,'BP input data'!$B$15,if( BJ2>'BP input data'!$B$14,min(BI35*(1+'BP input data'!$B$16),'BP input data'!$B$17),0)) -> 1000000
A36: Hosting | C36: =C32+C33 -> 2927.0833 | D36: =D32+D33 -> 8629.6988 | E36: =E32+E33 -> 14641.91 | F36: =F32+F33 -> 23389.119 | G36: =G32+G33 -> 32434.392 | H36: =H32+H33 -> 41865.038 | I36: =I32+I33 -> 52112.784 | J36: =J32+J33 -> 62982.358 | ... BJ36: =BJ32+BJ33 -> 6019679.8
A37: Team | B37: =Pre_launch_months*SUMPRODUCT( (Team_start_month <= COLUMN()-2) * (ISBLANK(Team_months) + (COLUMN()-2 <= (Team_start_month + Team_months -1))) * Team_value ) -> 78000 | C37: =SUMPRODUCT( (Team_start_month <= COLUMN()-2) * (ISBLANK(Team_months) + (COLUMN()-2 <= (Team_start_month + Team_months -1))) * Team_value ) -> 44500 | D37: =SUMPRODUCT( (Team_start_month <= COLUMN()-2) * (ISBLANK(Team_months) + (COLUMN()-2 <= (Team_start_month + Team_months -1))) * Team_value ) -> 44500 | E37: =SUMPRODUCT( (Team_start_month <= COLUMN()-2) * (ISBLANK(Team_months) + (COLUMN()-2 <= (Team_start_month + Team_months -1))) * Team_value ) -> 50500 | F37: =SUMPRODUCT( (Team_start_month <= COLUMN()-2) * (ISBLANK(Team_months) + (COLUMN()-2 <= (Team_start_month + Team_months -1))) * Team_value ) -> 62500 | G37: =SUMPRODUCT( (Team_start_month <= COLUMN()-2) * (ISBLANK(Team_months) + (COLUMN()-2 <= (Team_start_month + Team_months -1))) * Team_value ) -> 62500 | H37: =SUMPRODUCT( (Team_start_month <= COLUMN()-2) * (ISBLANK(Team_months) + (COLUMN()-2 <= (Team_start_month + Team_months -1))) * Team_value ) -> 62500 | I37: =SUMPRODUCT( (Team_start_month <= COLUMN()-2) * (ISBLANK(Team_months) + (COLUMN()-2 <= (Team_start_month + Team_months -1))) * Team_value ) -> 79000 | J37: =SUMPRODUCT( (Team_start_month <= COLUMN()-2) * (ISBLANK(Team_months) + (COLUMN()-2 <= (Team_start_month + Team_months -1))) * Team_value ) -> 79000 | ... BJ37: =SUMPRODUCT( (Team_start_month <= COLUMN()-2) * (ISBLANK(Team_months) + (COLUMN()-2 <= (Team_start_month + Team_months -1))) * Team_value ) -> 215500
A38: Services | B38: ='BP input data'!$B$63+'BP input data'!$B$66 -> 12000 | C38: ='BP input data'!$B$64+'BP input data'!$B$65+'BP input data'!$B$67 -> 3500 | D38: ='BP input data'!$B$64+'BP input data'!$B$65+'BP input data'!$B$67 -> 3500 | E38: ='BP input data'!$B$64+'BP input data'!$B$65+'BP input data'!$B$67 -> 3500 | F38: ='BP input data'!$B$64+'BP input data'!$B$65+'BP input data'!$B$67 -> 3500 | G38: ='BP input data'!$B$64+'BP input data'!$B$65+'BP input data'!$B$67 -> 3500 | H38: ='BP input data'!$B$64+'BP input data'!$B$65+'BP input data'!$B$67 -> 3500 | I38: ='BP input data'!$B$64+'BP input data'!$B$65+'BP input data'!$B$67 -> 3500 | J38: ='BP input data'!$B$64+'BP input data'!$B$65+'BP input data'!$B$67 -> 3500 | ... BJ38: ='BP input data'!$B$64+'BP input data'!$B$65+'BP input data'!$B$67 -> 3500
A39: Misc | B39: ='BP input data'!B71+('BP input data'!$B$4*'BP input data'!$B$70) -> 33000 | C39: ='BP input data'!$B$70 -> 1000 | D39: ='BP input data'!$B$70 -> 1000 | E39: ='BP input data'!$B$70 -> 1000 | F39: ='BP input data'!$B$70 -> 1000 | G39: ='BP input data'!$B$70 -> 1000 | H39: ='BP input data'!$B$70 -> 1000 | I39: ='BP input data'!$B$70+'BP input data'!$B$71 -> 28000 | J39: ='BP input data'!$B$70 -> 1000 | K39: ='BP input data'!$B$70 -> 1000 | L39: ='BP input data'!$B$70 -> 1000 | M39: ='BP input data'!$B$70 -> 1000 | N39: ='BP input data'!$B$70 -> 1000 | O39: ='BP input data'!$B$70 -> 1000 | P39: ='BP input data'!$B$70 -> 1000 | Q39: ='BP input data'!$B$70 -> 1000 | ... T39: ='BP input data'!$B$70 -> 1000 | U39: ='BP input data'!$B$70+'BP input data'!$B$71 -> 28000 | V39: ='BP input data'!$B$70 -> 1000 | W39: ='BP input data'!$B$70 -> 1000 | X39: ='BP input data'!$B$70 -> 1000 | Y39: ='BP input data'!$B$70 -> 1000 | Z39: ='BP input data'!$B$70 -> 1000 | AA39: ='BP input data'!$B$70 -> 1000 | AB39: ='BP input data'!$B$70 -> 1000 | AC39: ='BP input data'!$B$70 -> 1000 | ... AF39: ='BP input data'!$B$70 -> 1000 | AG39: ='BP input data'!$B$70+'BP input data'!$B$71 -> 28000 | AH39: ='BP input data'!$B$70 -> 1000 | AI39: ='BP input data'!$B$70 -> 1000 | AJ39: ='BP input data'!$B$70 -> 1000 | AK39: ='BP input data'!$B$70 -> 1000 | AL39: ='BP input data'!$B$70 -> 1000 | AM39: ='BP input data'!$B$70 -> 1000 | AN39: ='BP input data'!$B$70 -> 1000 | AO39: ='BP input data'!$B$70 -> 1000 | ... AR39: ='BP input data'!$B$70 -> 1000 | AS39: ='BP input data'!$B$70+'BP input data'!$B$71 -> 28000 | AT39: ='BP input data'!$B$70 -> 1000 | AU39: ='BP input data'!$B$70 -> 1000 | AV39: ='BP input data'!$B$70 -> 1000 | AW39: ='BP input data'!$B$70 -> 1000 | AX39: ='BP input data'!$B$70 -> 1000 | AY39: ='BP input data'!$B$70 -> 1000 | AZ39: ='BP input data'!$B$70 -> 1000 | BA39: ='BP input data'!$B$70 -> 1000 | ... BD39: ='BP input data'!$B$70 -> 1000 | BE39: ='BP input data'!$B$70+'BP input data'!$B$71 -> 28000 | BF39: ='BP input data'!$B$70 -> 1000 | BG39: ='BP input data'!$B$70 -> 1000 | BH39: ='BP input data'!$B$70 -> 1000 | BI39: ='BP input data'!$B$70 -> 1000 | BJ39: ='BP input data'!$B$70 -> 1000
A40: Costs | B40: =sum(B34:B39) -> 383000 | C40: =sum(C34:C39) -> 56927.083 | D40: =sum(D34:D39) -> 63879.699 | E40: =sum(E34:E39) -> 77454.41 | F40: =sum(F34:F39) -> 100154.74 | G40: =sum(G34:G39) -> 111641.42 | H40: =sum(H34:H39) -> 124123.83 | I40: =sum(I34:I39) -> 181686.27 | ... BJ40: =sum(BJ34:BJ39) -> 7239679.8
A41: Cumulative costs | B41: =B40 -> 383000 | C41: =B41+C40 -> 439927.08 | D41: =C41+D40 -> 503806.78 | E41: =D41+E40 -> 581261.19 | F41: =E41+F40 -> 681415.94 | G41: =F41+G40 -> 793057.36 | H41: =G41+H40 -> 917181.19 | I41: =H41+I40 -> 1098867.5 | J41: =I41+J40 -> 1269191.7 | ... BJ41: =BI41+BJ40 -> 1.8965849e+08
...

Sheet BP input data
A1: Name | B1: Value | C1: Start month | D1: Months | E1: Description | F1: Source | G1: Link
A2: General
A3: Currency | B3: USD ($) | F3: Control/input
A4: Pre-launch months | B4: 6 | F4: Assumption
A5: Monthly/yearly subscription split | B5: =Summary!B9 -> 0.1 | F5: Assumption
A7: Sales
A8: Month CEO stops with founder-led sales | B8: =Summary!B2 -> 10 | F8: Control/input
A9: BD sales per month (Basic) | B9: =Summary!B6 -> 5 | F9: Assumption
A10: BD sales per month (Pro) | B10: =Summary!B7 -> 3 | F10: Assumption
A11: BD sales per month (Enterprise) | B11: =Summary!B8 -> 1 | F11: Assumption
A13: Marketing
A14: Online marketing start month | B14: =Summary!B12 -> 1 | E14: When does paid advertising start? | F14: Control/input
A15: Initial monthly marketing spend | B15: =Summary!B13 -> 5000 | F15: Control/input
A16: Marketing spend growth | B16: =Summary!B14 -> 0.25 | E16: Monthly advertising spend growth | F16: Control/input
A17: Marketing spend cap | B17: =Summary!B15 -> 1000000 | E17: Maximum advertising spend | F17: Control/input
A18: Basic tier marketing % split | B18: =Summary!B10 -> 0.1 | E18: % of marketing to Basic tier customers | F18: Control/input
A19: Pro tier marketing % split | B19: =Summary!B11 -> 0.1 | E19: % of marketing to Pro tier customers | F19: Control/input
A20: Enterprise tier marketing % split | B20: =1-B18-B19 -> 0.8 | E20: % of marketing to Enterprise tier customers | F20: Calculated
A21: CAC (Basic) | B21: =Summary!B16 -> 800 | E21: Basic tier customer acquisition cost | F21: Assumption
A22: CAC (Pro) | B22: =Summary!B17 -> 1200 | E22: Pro tier customer acquisition cost | F22: Assumption
A23: CAC (Enterprise) | B23: =Summary!B18 -> 1500 | E23: Enterprise tier customer acquisition cost | F23: Assumption
A24: CAC growth | B24: =Summary!B19 -> 0.01 | E24: Monthly CAC growth | F24: Assumption
A25: CAC cap | B25: =Summary!B20 -> 2 | E25: Maximum CAC (as a % of initial CAC) | F25: Assumption
A26: Churn (Basic) | B26: =Summary!B21 -> 0.01 | E26: Basic tier monthly churn | F26: Assumption
A27: Churn (Pro) | B27: =Summary!B22 -> 0.005 | E27: Pro tier monthly churn | F27: Assumption
A28: Churn (Enterprise) | B28: =Summary!B23 -> 0.0025 | E28: Enterprise tier monthly churn | F28: Assumption
A30: Hosting
A31: Fixed | B31: 2000 | E31: Fixed hosting monthly cost | F31: Assumption
A32: Fixed growth | B32: 0.01 | E32: Fixed hosting cost monthly growth | F32: Assumption
A33: Variable | B33: 250 | E33: Per customer monthly cost | F33: Assumption
A35: Team
A36: CEO (Y1) | B36: 6000 | C36: 0 | D36: 12 | E36: CEO year 1 | F36: Control/input
A37: CEO (Y2+) | B37: 10000 | C37: 13 | E37: CEO year 2 | F37: Control/input
A38: CTO | B38: 8000 | C38: 1 | E38: Founding CTO | F38: Control/input
A39: SOC analyst #1 | B39: 5000 | C39: 0 | F39: Control/input
A40: Web developer #1 | B40: 6000 | C40: 4 | E40: Web developer after launch | F40: Control/input
A41: Back-end developer #1 | B41: 6000 | C41: 4 | E41: Back-end developer after launch | F41: Control/input
A42: Back-end developer #2 | B42: 6000 | C42: 7 | E42: Back-end developer 6-months after launch | F42: Control/input
A43: AI/Data engineer #1 | B43: 6000 | C43: 1 | E43: For developing additional AI modules | F43: Control/input
A44: Data scientist #1 | B44: 6000 | C44: 3 | F44: Control/input
...

Sheet Business model
A1: Name | B1: Value | C1: Description
A2: Basic monthly subscription | B2: 1000 | C2: Smaller FIs, healthcare providers, SMBs. Features: self-service, AI chatbot, knowledge base
A3: Basic yearly subscription | B3: 10000
A4: Pro monthly subscription | B4: 5000 | C4: Mid-market banks, hospital systems Features: API access, priority support
A5: Pro yearly subscription | B5: 50000
A6: Enterprise monthly subscription | B6: 8000 | C6: Large FIs, healthcare systems, multinationals Features: SOC 2/HIPAA bundle, tailored support
A7: Enterprise yearly subscription | B7: 80000
A8: Module min price | B8: 500 | C8: Examples: specialised compliance frameworks beyond core bundle (e.g., ISO 27001, SOX, sector-specific templates). Buyers: typically Pro/Enterprise customers expanding coverage. Timing: from Version 1 (post-MVP) onwards.
A9: Module max price | B9: 5000
A11: NOTE: This model does not currently include consulting/professional services, usage based pricing, the partner marketplace or the certification program which are all possible future revenue streams.
